Workbook

Sheet Totales
B2: Tamaño de Matriz | C2: Numero de hilos | D2: ForK - PC local | E2: Fork - Maquina Virtual | F2: OpenMP - PC local | G2: OpenMP - Maquina Virtual | H2: Posix - PC local | I2: Posix - Maquina Virtual
B3: 15x15 | C3: 1 Hilo | D3: =AVERAGE('15x15'!C4:C33) -> 301.2 | E3: =AVERAGE('15x15'!D4:D33) -> 784.63333 | F3: =AVERAGE('15x15'!E4:E33) -> 7.5666667 | G3: =AVERAGE('15x15'!F4:F33) -> 12.333333 | H3: =AVERAGE('15x15'!G4:G33) -> 367.26667 | I3: =AVERAGE('15x15'!H4:H33) -> 684.1
C4: 2 Hilos | D4: =AVERAGE('15x15'!C34:C63) -> 382.13333 | E4: =AVERAGE('15x15'!D34:D63) -> 1249.4333 | F4: =AVERAGE('15x15'!E34:E63) -> 121.2 | G4: =AVERAGE('15x15'!F34:F63) -> 228.03333 | H4: =AVERAGE('15x15'!G34:G63) -> 407.26667 | I4: =AVERAGE('15x15'!H34:H63) -> 882
C5: 4 Hilos | D5: =AVERAGE('15x15'!C64:C93) -> 554.13333 | E5: =AVERAGE('15x15'!D64:D94) -> 1849.8065 | F5: =AVERAGE('15x15'!E64:E94) -> 441.58065 | G5: =AVERAGE('15x15'!F64:F94) -> 2350.1613 | H5: =AVERAGE('15x15'!G64:G94) -> 699.22581 | I5: =AVERAGE('15x15'!H64:H94) -> 1301.4194
C6: 8 Hilos | D6: =AVERAGE('15x15'!C94:C123) -> 1051.9333 | E6: =AVERAGE('15x15'!D94:D123) -> 3072.9 | F6: =AVERAGE('15x15'!E94:E123) -> 583.2 | G6: =AVERAGE('15x15'!F94:F123) -> 1011.7667 | H6: =AVERAGE('15x15'!G94:G123) -> 1068.6667 | I6: =AVERAGE('15x15'!H94:H123) -> 1440.6333
B7: 50x50 | C7: 1 Hilo | D7: =AVERAGE('50x50'!C4:C33) -> 398.33333 | E7: =AVERAGE('50x50'!D4:D33) -> 961.13333 | F7: =AVERAGE('50x50'!E4:E33) -> 112.56667 | G7: =AVERAGE('50x50'!F4:F33) -> 139.3 | H7: =AVERAGE('50x50'!G4:G33) -> 460.63333 | I7: =AVERAGE('50x50'!H4:H33) -> 990.76667
C8: 2 Hilos | D8: =AVERAGE('50x50'!C34:C63) -> 445.96667 | E8: =AVERAGE('50x50'!D34:D63) -> 1488.9667 | F8: =AVERAGE('50x50'!E34:E63) -> 174.03333 | G8: =AVERAGE('50x50'!F34:F63) -> 223.53333 | H8: =AVERAGE('50x50'!G34:G63) -> 596.8 | I8: =AVERAGE('50x50'!H34:H63) -> 1088.2667
C9: 4 Hilos | D9: =AVERAGE('50x50'!C64:C93) -> 577.66667 | E9: =AVERAGE('50x50'!D64:D93) -> 2242.2667 | F9: =AVERAGE('50x50'!E64:E93) -> 268.23333 | G9: =AVERAGE('50x50'!F64:F93) -> 1651.4667 | H9: =AVERAGE('50x50'!G64:G93) -> 729.33333 | I9: =AVERAGE('50x50'!H64:H93) -> 1485.3
C10: 8 Hilos | D10: =AVERAGE('50x50'!C94:C123) -> 1017.8333 | E10: =AVERAGE('50x50'!D94:D123) -> 3558.2 | F10: =AVERAGE('50x50'!E94:E123) -> 616.16667 | G10: =AVERAGE('50x50'!F94:F123) -> 1036.3667 | H10: =AVERAGE('50x50'!G94:G123) -> 1228.5 | I10: =AVERAGE('50x50'!H94:H123) -> 2188.8667
B11: 100x100 | C11: 1 Hilo | D11: =AVERAGE('100x100'!C4:C33) -> 1302.5667 | E11: =AVERAGE('100x100'!D4:D33) -> 2331.2 | F11: =AVERAGE('100x100'!E4:E33) -> 916.73333 | G11: =AVERAGE('100x100'!F4:F33) -> 1092.8667 | H11: =AVERAGE('100x100'!G4:G33) -> 1522.8667 | I11: =AVERAGE('100x100'!H4:H33) -> 2193.9
C12: 2 Hilos | D12: =AVERAGE('100x100'!C34:C63) -> 913.4 | E12: =AVERAGE('100x100'!D34:D63) -> 2009.9 | F12: =AVERAGE('100x100'!E34:E63) -> 693.56667 | G12: =AVERAGE('100x100'!F34:F63) -> 985.23333 | H12: =AVERAGE('100x100'!G34:G63) -> 1441.7667 | I12: =AVERAGE('100x100'!H34:H63) -> 2732.1
C13: 4 Hilos | D13: =AVERAGE('100x100'!C64:C93) -> 921 | E13: =AVERAGE('100x100'!D64:D93) -> 2975.8 | F13: =AVERAGE('100x100'!E64:E93) -> 772.66667 | G13: =AVERAGE('100x100'!F64:F93) -> 1736.3333 | H13: =AVERAGE('100x100'!G64:G93) -> 1719.7667 | I13: =AVERAGE('100x100'!H64:H93) -> 3248.8333
C14: 8 Hilos | D14: =AVERAGE('100x100'!C94:C123) -> 1234.1 | E14: =AVERAGE('100x100'!D94:D123) -> 3405.9667 | F14: =AVERAGE('100x100'!E94:E123) -> 987.2 | G14: =AVERAGE('100x100'!F94:F123) -> 1223.8333 | H14: =AVERAGE('100x100'!G94:G123) -> 1873.7667 | I14: =AVERAGE('100x100'!H94:H123) -> 4169.3333
B15: 200x200 | C15: 1 Hilo | D15: =AVERAGE('200x200'!C4:C33) -> 9363.2667 | E15: =AVERAGE('200x200'!D4:D33) -> 13202.033 | F15: =AVERAGE('200x200'!E4:E33) -> 7908.8 | G15: =AVERAGE('200x200'!F4:F33) -> 9104.5333 | H15: =AVERAGE('200x200'!G4:G33) -> 10382.933 | I15: =AVERAGE('200x200'!H4:H33) -> 14985.567
C16: 2 Hilos | D16: =AVERAGE('200x200'!C34:C63) -> 4903.9667 | E16: =AVERAGE('200x200'!D34:D63) -> 8810.1667 | F16: =AVERAGE('200x200'!E34:E63) -> 5894.8 | G16: =AVERAGE('200x200'!F34:F63) -> 5179.0667 | H16: =AVERAGE('200x200'!G34:G63) -> 7168.3333 | I16: =AVERAGE('200x200'!H34:H63) -> 10974.6
C17: 4 Hilos | D17: =AVERAGE('200x200'!C64:C93) -> 3192.4 | E17: =AVERAGE('200x200'!D64:D93) -> 6807.0667 | F17: =AVERAGE('200x200'!E64:E93) -> 2655.5 | G17: =AVERAGE('200x200'!F64:F93) -> 3718.2667 | H17: =AVERAGE('200x200'!G64:G93) -> 7440.9 | I17: =AVERAGE('200x200'!H64:H93) -> 10073.133
C18: 8 Hilos | D18: =AVERAGE('200x200'!C94:C123) -> 2322.7333 | E18: =AVERAGE('200x200'!D94:D123) -> 8009.2333 | F18: =AVERAGE('200x200'!E94:E123) -> 2604.5667 | G18: =AVERAGE('200x200'!F94:F123) -> 5042.6 | H18: =AVERAGE('200x200'!G94:G123) -> 8738.6667 | I18: =AVERAGE('200x200'!H94:H123) -> 9772.2333
B20: Tamaño de Matriz | C20: Numero de hilos | D20: ForK - PC local | E20: Fork - Maquina Virtual | F20: OpenMP - PC local | G20: OpenMP - Maquina Virtual | H20: Posix - PC local | I20: Posix - Maquina Virtual
B21: 15x15 | C21: 2 Hilos | D21: =D$3/D4 -> 0.78820656 | E21: =E$3/E4 -> 0.62799136 | F21: =F$3/F4 -> 0.062431243 | G21: =G$3/G4 -> 0.05408566 | H21: =H$3/H4 -> 0.90178425 | I21: =I$3/I4 -> 0.77562358
C22: 4 Hilos | D22: =D$3/D5 -> 0.54355149 | E22: =E$3/E5 -> 0.4241705 | F22: =F$3/F5 -> 0.017135413 | G22: =G$3/G5 -> 0.0052478668 | H22: =H$3/H5 -> 0.52524759 | I22: =I$3/I5 -> 0.52565685
C23: 8 Hilos | D23: =D$3/D6 -> 0.28632993 | E23: =E$3/E6 -> 0.25533969 | F23: =F$3/F6 -> 0.012974394 | G23: =G$3/G6 -> 0.012189899 | H23: =H$3/H6 -> 0.34366812 | I23: =I$3/I6 -> 0.47486059
B24: 50x50 | C24: 2 Hilos | D24: =D$7/D8 -> 0.89319082 | E24: =E$7/E8 -> 0.64550359 | F24: =F$7/F8 -> 0.64681096 | G24: =G$7/G8 -> 0.62317328 | H24: =H$7/H8 -> 0.7718387 | I24: =I$7/I8 -> 0.91040799
C25: 4 Hilos | D25: =D$7/D9 -> 0.68955568 | E25: =E$7/E9 -> 0.42864363 | F25: =F$7/F9 -> 0.4196595 | G25: =G$7/G9 -> 0.084349265 | H25: =H$7/H9 -> 0.63158135 | I25: =I$7/I9 -> 0.66704818
C26: 8 Hilos | D26: =D$7/D10 -> 0.39135418 | E26: =E$7/E10 -> 0.27011785 | F26: =F$7/F10 -> 0.18268867 | G26: =G$7/G10 -> 0.13441189 | H26: =H$7/H10 -> 0.37495591 | I26: =I$7/I10 -> 0.45263911
B27: 100x100 | C27: 2 Hilos | D27: =D$11/D12 -> 1.4260638 | E27: =E$11/E12 -> 1.1598587 | F27: =F$11/F12 -> 1.3217667 | G27: =G$11/G12 -> 1.1092465 | H27: =H$11/H12 -> 1.0562504 | I27: =I$11/I12 -> 0.80300867
C28: 4 Hilos | D28: =D$11/D13 -> 1.4142961 | E28: =E$11/E13 -> 0.78338598 | F28: =F$11/F13 -> 1.1864538 | G28: =G$11/G13 -> 0.62941064 | H28: =H$11/H13 -> 0.88550772 | I28: =I$11/I13 -> 0.67528857
C29: 8 Hilos | D29: =D$11/D14 -> 1.055479 | E29: =E$11/E14 -> 0.68444592 | F29: =F$11/F14 -> 0.92861967 | G29: =G$11/G14 -> 0.89298652 | H29: =H$11/H14 -> 0.81273015 | I29: =I$11/I14 -> 0.52619923
B30: 200x200 | C30: 2 Hilos | D30: =D$15/D16 -> 1.9093251 | E30: =E$15/E16 -> 1.4984998 | F30: =F$15/F16 -> 1.3416571 | G30: =G$15/G16 -> 1.7579487 | H30: =H$15/H16 -> 1.4484445 | I30: =I$15/I16 -> 1.3654773
C31: 4 Hilos | D31: =D$15/D17 -> 2.9329867 | E31: =E$15/E17 -> 1.93946 | F31: =F$15/F17 -> 2.9782715 | G31: =G$15/G17 -> 2.4485961 | H31: =H$15/H17 -> 1.3953868 | I31: =I$15/I17 -> 1.4876768
C32: 8 Hilos | D32: =D$15/D18 -> 4.0311415 | E32: =E$15/E18 -> 1.6483517 | F32: =F$15/F18 -> 3.0365128 | G32: =G$15/G18 -> 1.8055236 | H32: =H$15/H18 -> 1.1881599 | I32: =I$15/I18 -> 1.5334843

Sheet 15x15
C2: Fork | E2: OpenMP | G2: Posix
B3: Numero de hilos | C3: ForK - PC local | D3: Fork - Maquina Virtual | E3: OpenMP - PC local | F3: OpenMP - Maquina Virtual | G3: Posix - PC local | H3: Posix - Maquina Virtual
B4: 1 | C4: 272 | D4: 708 | E4: 10 | F4: 13 | G4: 375 | H4: 652
C5: 287 | D5: 635 | E5: 7 | F5: 11 | G5: 385 | H5: 639
C6: 391 | D6: 1254 | E6: 8 | F6: 11 | G6: 357 | H6: 715
C7: 268 | D7: 959 | E7: 7 | F7: 11 | G7: 319 | H7: 1066
C8: 263 | D8: 763 | E8: 7 | F8: 10 | G8: 307 | H8: 621
C9: 301 | D9: 568 | E9: 7 | F9: 17 | G9: 309 | H9: 581
C10: 280 | D10: 548 | E10: 9 | F10: 10 | G10: 323 | H10: 1010
C11: 330 | D11: 845 | E11: 6 | F11: 12 | G11: 310 | H11: 552
C12: 258 | D12: 659 | E12: 6 | F12: 12 | G12: 330 | H12: 544
C13: 319 | D13: 847 | E13: 6 | F13: 12 | G13: 298 | H13: 626
C14: 317 | D14: 751 | E14: 7 | F14: 13 | G14: 318 | H14: 632
C15: 260 | D15: 934 | E15: 9 | F15: 14 | G15: 467 | H15: 616
C16: 356 | D16: 786 | E16: 6 | F16: 13 | G16: 350 | H16: 634
... C33: 285 | D33: 675 | E33: 6 | F33: 11 | G33: 314 | H33: 785
B34: 2 | C34: 370 | D34: 2180 | E34: 157 | F34: 114 | G34: 376 | H34: 635
C35: 516 | D35: 1484 | E35: 134 | F35: 186 | G35: 432 | H35: 657
C36: 445 | D36: 1706 | E36: 111 | F36: 185 | G36: 337 | H36: 573
C37: 513 | D37: 1535 | E37: 103 | F37: 112 | G37: 361 | H37: 916
C38: 432 | D38: 3005 | E38: 179 | F38: 133 | G38: 378 | H38: 627
C39: 367 | D39: 1605 | E39: 116 | F39: 114 | G39: 466 | H39: 1825
C40: 348 | D40: 835 | E40: 108 | F40: 1171 | G40: 368 | H40: 575
C41: 333 | D41: 977 | E41: 110 | F41: 158 | G41: 445 | H41: 570
C42: 448 | D42: 1082 | E42: 116 | F42: 180 | G42: 447 | H42: 988
C43: 366 | D43: 4940 | E43: 113 | F43: 113 | G43: 422 | H43: 778
C44: 343 | D44: 724 | E44: 104 | F44: 135 | G44: 385 | H44: 984
C45: 324 | D45: 777 | E45: 98 | F45: 125 | G45: 416 | H45: 1572
C46: 493 | D46: 1238 | E46: 100 | F46: 111 | G46: 352 | H46: 970
... C63: 377 | D63: 855 | E63: 100 | F63: 1491 | G63: 428 | H63: 1851
B64: 4 | C64: 548 | D64: 1515 | E64: 937 | F64: 4153 | G64: 652 | H64: 709
C65: 481 | D65: 1464 | E65: 240 | F65: 11516 | G65: 1910 | H65: 1318
C66: 570 | D66: 1487 | E66: 241 | F66: 663 | G66: 575 | H66: 1229
C67: 540 | D67: 4866 | E67: 240 | F67: 374 | G67: 607 | H67: 812
C68: 517 | D68: 1343 | E68: 220 | F68: 271 | G68: 615 | H68: 1448
C69: 493 | D69: 1327 | E69: 277 | F69: 3791 | G69: 529 | H69: 1455
C70: 585 | D70: 1261 | E70: 1506 | F70: 315 | G70: 663 | H70: 1078
C71: 554 | D71: 1353 | E71: 583 | F71: 385 | G71: 683 | H71: 1769
C72: 458 | D72: 1179 | E72: 587 | F72: 3081 | G72: 567 | H72: 718
C73: 536 | D73: 1238 | E73: 265 | F73: 7392 | G73: 1025 | H73: 916
...

Sheet 50x50
C2: Fork | E2: OpenMP | G2: Posix
B3: Numero de hilos | C3: ForK - PC local | D3: Fork - Maquina Virtual | E3: OpenMP - PC local | F3: OpenMP - Maquina Virtual | G3: Posix - PC local | H3: Posix - Maquina Virtual
B4: 1 | C4: 344 | D4: 879 | E4: 100 | F4: 120 | G4: 494 | H4: 907
C5: 338 | D5: 728 | E5: 100 | F5: 120 | G5: 494 | H5: 710
C6: 344 | D6: 1048 | E6: 100 | F6: 118 | G6: 427 | H6: 705
C7: 409 | D7: 958 | E7: 100 | F7: 100 | G7: 445 | H7: 2077
C8: 333 | D8: 711 | E8: 100 | F8: 119 | G8: 421 | H8: 1069
C9: 514 | D9: 1105 | E9: 100 | F9: 118 | G9: 515 | H9: 923
C10: 341 | D10: 744 | E10: 101 | F10: 118 | G10: 450 | H10: 1097
C11: 464 | D11: 724 | E11: 119 | F11: 131 | G11: 451 | H11: 773
C12: 359 | D12: 1723 | E12: 149 | F12: 118 | G12: 488 | H12: 727
C13: 358 | D13: 1176 | E13: 100 | F13: 118 | G13: 479 | H13: 705
C14: 346 | D14: 991 | E14: 100 | F14: 124 | G14: 462 | H14: 710
C15: 345 | D15: 831 | E15: 125 | F15: 118 | G15: 446 | H15: 899
C16: 419 | D16: 767 | E16: 100 | F16: 118 | G16: 456 | H16: 1415
... C33: 420 | D33: 968 | E33: 119 | F33: 325 | G33: 456 | H33: 728
B34: 2 | C34: 526 | D34: 870 | E34: 145 | F34: 179 | G34: 616 | H34: 765
C35: 402 | D35: 804 | E35: 145 | F35: 198 | G35: 631 | H35: 933
C36: 476 | D36: 1132 | E36: 149 | F36: 326 | G36: 589 | H36: 846
C37: 404 | D37: 1032 | E37: 159 | F37: 199 | G37: 732 | H37: 2324
C38: 470 | D38: 1933 | E38: 319 | F38: 180 | G38: 508 | H38: 3763
C39: 405 | D39: 986 | E39: 154 | F39: 169 | G39: 511 | H39: 1379
C40: 389 | D40: 1380 | E40: 155 | F40: 167 | G40: 535 | H40: 727
C41: 404 | D41: 1075 | E41: 158 | F41: 168 | G41: 593 | H41: 707
C42: 372 | D42: 919 | E42: 220 | F42: 167 | G42: 586 | H42: 776
C43: 393 | D43: 982 | E43: 151 | F43: 175 | G43: 587 | H43: 1354
C44: 410 | D44: 1253 | E44: 141 | F44: 336 | G44: 522 | H44: 757
C45: 488 | D45: 1094 | E45: 141 | F45: 173 | G45: 800 | H45: 1067
C46: 452 | D46: 1201 | E46: 153 | F46: 173 | G46: 508 | H46: 1004
... C63: 369 | D63: 808 | E63: 201 | F63: 179 | G63: 568 | H63: 771
B64: 4 | C64: 575 | D64: 2620 | E64: 241 | F64: 3787 | G64: 632 | H64: 1407
C65: 690 | D65: 1994 | E65: 252 | F65: 590 | G65: 612 | H65: 998
C66: 534 | D66: 7548 | E66: 242 | F66: 286 | G66: 745 | H66: 2402
C67: 706 | D67: 1853 | E67: 238 | F67: 346 | G67: 866 | H67: 2307
C68: 543 | D68: 2193 | E68: 263 | F68: 2375 | G68: 648 | H68: 1524
C69: 600 | D69: 2655 | E69: 229 | F69: 345 | G69: 523 | H69: 1007
C70: 523 | D70: 2477 | E70: 250 | F70: 277 | G70: 617 | H70: 1174
C71: 758 | D71: 1940 | E71: 236 | F71: 346 | G71: 855 | H71: 1104
C72: 518 | D72: 3186 | E72: 278 | F72: 1922 | G72: 791 | H72: 925
C73: 591 | D73: 1471 | E73: 251 | F73: 282 | G73: 913 | H73: 1764
...

Sheet 100x100
C2: Fork | E2: OpenMP | G2: Posix
B3: Numero de hilos | C3: ForK - PC local | D3: Fork - Maquina Virtual | E3: OpenMP - PC local | F3: OpenMP - Maquina Virtual | G3: Posix - PC local | H3: Posix - Maquina Virtual
B4: 1 | C4: 1259 | D4: 5201 | E4: 848 | F4: 845 | G4: 1605 | H4: 2244
C5: 1585 | D5: 1979 | E5: 847 | F5: 816 | G5: 1413 | H5: 2084
C6: 1259 | D6: 2886 | E6: 832 | F6: 1050 | G6: 1436 | H6: 2828
C7: 1607 | D7: 3117 | E7: 867 | F7: 925 | G7: 1330 | H7: 2297
C8: 1255 | D8: 1882 | E8: 829 | F8: 886 | G8: 1377 | H8: 2474
C9: 1305 | D9: 2605 | E9: 841 | F9: 2308 | G9: 1508 | H9: 1910
C10: 1151 | D10: 2453 | E10: 836 | F10: 1288 | G10: 1590 | H10: 2045
C11: 1537 | D11: 2428 | E11: 1098 | F11: 997 | G11: 1763 | H11: 1870
C12: 1252 | D12: 2022 | E12: 836 | F12: 813 | G12: 1451 | H12: 1898
C13: 1144 | D13: 1820 | E13: 816 | F13: 1022 | G13: 1342 | H13: 2653
C14: 1522 | D14: 2032 | E14: 816 | F14: 849 | G14: 1701 | H14: 2076
C15: 1379 | D15: 2989 | E15: 841 | F15: 941 | G15: 1555 | H15: 3011
C16: 1149 | D16: 1991 | E16: 1019 | F16: 831 | G16: 1366 | H16: 1937
... C33: 1387 | D33: 1945 | E33: 1003 | F33: 818 | G33: 1335 | H33: 1968
B34: 2 | C34: 923 | D34: 1486 | E34: 528 | F34: 763 | G34: 1127 | H34: 2004
C35: 943 | D35: 1530 | E35: 640 | F35: 587 | G35: 1978 | H35: 2223
C36: 899 | D36: 1474 | E36: 696 | F36: 623 | G36: 1751 | H36: 2204
C37: 893 | D37: 1486 | E37: 701 | F37: 917 | G37: 2036 | H37: 1554
C38: 925 | D38: 1716 | E38: 528 | F38: 1526 | G38: 1975 | H38: 2238
C39: 885 | D39: 2322 | E39: 594 | F39: 736 | G39: 1124 | H39: 1608
C40: 959 | D40: 1609 | E40: 604 | F40: 605 | G40: 1461 | H40: 1929
C41: 921 | D41: 3571 | E41: 522 | F41: 801 | G41: 1613 | H41: 1808
C42: 1154 | D42: 3983 | E42: 512 | F42: 739 | G42: 1464 | H42: 2294
C43: 1162 | D43: 1762 | E43: 855 | F43: 3820 | G43: 1210 | H43: 4274
C44: 779 | D44: 4533 | E44: 633 | F44: 674 | G44: 1336 | H44: 1783
C45: 970 | D45: 1747 | E45: 672 | F45: 577 | G45: 1855 | H45: 1698
C46: 1127 | D46: 2008 | E46: 731 | F46: 677 | G46: 1889 | H46: 1727
... C63: 775 | D63: 1449 | E63: 522 | F63: 810 | G63: 1536 | H63: 1851
B64: 4 | C64: 789 | D64: 3168 | E64: 725 | F64: 6746 | G64: 1980 | H64: 3110
C65: 1017 | D65: 3151 | E65: 676 | F65: 2506 | G65: 1858 | H65: 2902
C66: 794 | D66: 4768 | E66: 950 | F66: 473 | G66: 1961 | H66: 5525
C67: 851 | D67: 4985 | E67: 938 | F67: 573 | G67: 1423 | H67: 2596
C68: 799 | D68: 2689 | E68: 812 | F68: 531 | G68: 1850 | H68: 6979
C69: 985 | D69: 5695 | E69: 767 | F69: 2612 | G69: 1768 | H69: 5212
C70: 913 | D70: 1658 | E70: 725 | F70: 2969 | G70: 2043 | H70: 3613
C71: 1149 | D71: 3971 | E71: 666 | F71: 4330 | G71: 1477 | H71: 2867
C72: 977 | D72: 1895 | E72: 692 | F72: 4486 | G72: 1694 | H72: 1776
C73: 932 | D73: 2030 | E73: 700 | F73: 2353 | G73: 1556 | H73: 1705
...

Sheet 200x200
C2: Fork | E2: OpenMP | G2: Posix
B3: Numero de hilos | C3: ForK - PC local | D3: Fork - Maquina Virtual | E3: OpenMP - PC local | F3: OpenMP - Maquina Virtual | G3: Posix - PC local | H3: Posix - Maquina Virtual
B4: 1 | C4: 9070 | D4: 13351 | E4: 7020 | F4: 8458 | G4: 9978 | H4: 22261
C5: 9164 | D5: 12210 | E5: 6887 | F5: 11437 | G5: 10398 | H5: 21980
C6: 9830 | D6: 11917 | E6: 6768 | F6: 8485 | G6: 10233 | H6: 15280
C7: 10432 | D7: 12036 | E7: 7887 | F7: 10229 | G7: 10820 | H7: 22261
C8: 9708 | D8: 11776 | E8: 7034 | F8: 9201 | G8: 9982 | H8: 17144
C9: 9815 | D9: 11925 | E9: 7036 | F9: 9440 | G9: 10614 | H9: 19019
C10: 9929 | D10: 14094 | E10: 7426 | F10: 8707 | G10: 10575 | H10: 15523
C11: 9097 | D11: 12532 | E11: 7165 | F11: 8933 | G11: 10134 | H11: 16347
C12: 8972 | D12: 11982 | E12: 7861 | F12: 10059 | G12: 9929 | H12: 13672
C13: 9115 | D13: 12013 | E13: 7344 | F13: 8841 | G13: 10275 | H13: 14308
C14: 9074 | D14: 16840 | E14: 7851 | F14: 8430 | G14: 11104 | H14: 16021
C15: 9105 | D15: 14246 | E15: 7339 | F15: 8421 | G15: 10539 | H15: 17467
C16: 9713 | D16: 13602 | E16: 7100 | F16: 10839 | G16: 10936 | H16: 14221
... C33: 9314 | D33: 13272 | E33: 7603 | F33: 8821 | G33: 10221 | H33: 12842
B34: 2 | C34: 4875 | D34: 8501 | E34: 7595 | F34: 5951 | G34: 6863 | H34: 10157
C35: 4906 | D35: 7581 | E35: 5741 | F35: 5009 | G35: 7252 | H35: 9272
C36: 5133 | D36: 10432 | E36: 7482 | F36: 4485 | G36: 6333 | H36: 9233
C37: 4819 | D37: 7430 | E37: 4074 | F37: 5280 | G37: 6525 | H37: 9631
C38: 4741 | D38: 8650 | E38: 4415 | F38: 4609 | G38: 5797 | H38: 9997
C39: 4795 | D39: 7493 | E39: 4743 | F39: 4803 | G39: 7823 | H39: 9544
C40: 5122 | D40: 8737 | E40: 5245 | F40: 4516 | G40: 6874 | H40: 10288
C41: 4682 | D41: 10593 | E41: 6026 | F41: 5687 | G41: 6755 | H41: 10158
C42: 4993 | D42: 10090 | E42: 4094 | F42: 4968 | G42: 6934 | H42: 9532
C43: 5035 | D43: 10618 | E43: 7545 | F43: 4345 | G43: 7288 | H43: 9648
C44: 4928 | D44: 11267 | E44: 9041 | F44: 4532 | G44: 7537 | H44: 12129
C45: 4846 | D45: 9006 | E45: 3841 | F45: 4680 | G45: 7163 | H45: 16226
C46: 4849 | D46: 14465 | E46: 3753 | F46: 4563 | G46: 6431 | H46: 12719
... C63: 4995 | D63: 7348 | E63: 3933 | F63: 4482 | G63: 6949 | H63: 11614
B64: 4 | C64: 3063 | D64: 5144 | E64: 2216 | F64: 3625 | G64: 7542 | H64: 12659
C65: 3208 | D65: 5724 | E65: 2275 | F65: 3110 | G65: 7798 | H65: 12192
C66: 3187 | D66: 6897 | E66: 2286 | F66: 2699 | G66: 7596 | H66: 10678
C67: 3569 | D67: 7887 | E67: 2276 | F67: 2566 | G67: 7383 | H67: 9976
C68: 3226 | D68: 5249 | E68: 2034 | F68: 2718 | G68: 7851 | H68: 9898
C69: 3276 | D69: 6291 | E69: 2079 | F69: 2564 | G69: 7591 | H69: 10403
C70: 3050 | D70: 6930 | E70: 2412 | F70: 2815 | G70: 7484 | H70: 9750
C71: 3379 | D71: 5248 | E71: 2261 | F71: 2610 | G71: 7329 | H71: 9006
C72: 3337 | D72: 6007 | E72: 2330 | F72: 2660 | G72: 7680 | H72: 11481
C73: 3264 | D73: 4688 | E73: 2179 | F73: 3098 | G73: 7261 | H73: 12722
...
